Workbook

Sheet Cover
D11: View HR Limited
D12: EBITDA Business Valuation report
D13: for the board of directors

Sheet Ebitda
A1: =Cover!D11 -> View HR Limited
A2: EBITDA Financials
C4: 2025 | E4: 2024 | G4: 2023 | I4: Avg Total
C5: £ | E5: £ | G5: £
A7: Turnover | C7: ='Ebitda workings'!O9 -> 859085 | E7: ='Ebitda workings'!Q9 -> 664804 | G7: ='Ebitda workings'!S9 -> 549888
A9: Cost of Sales | C9: ='Ebitda workings'!O15 -> -46743 | E9: ='Ebitda workings'!Q15 -> -57960 | G9: ='Ebitda workings'!S15 -> -48569
A11: GROSS PROFIT | C11: =SUM(C7:C10) -> 812342 | E11: =SUM(E7:E10) -> 606844 | G11: =SUM(G7:G10) -> 501319
A13: Administrative Expenses | C13: ='Ebitda workings'!O47 -> -589651.23 | E13: ='Ebitda workings'!Q47 -> -329250.8 | G13: ='Ebitda workings'!S47 -> -266856.8
A15: Other operating income | C15: ='Ebitda workings'!O10 -> 462 | E15: ='Ebitda workings'!Q10 -> 900 | G15: ='Ebitda workings'!S10 -> 420
A17: EBITDA | C17: =SUM(C11:C16) -> 223152.77 | E17: =SUM(E11:E16) -> 278493.2 | G17: =SUM(G11:G16) -> 234882.2 | I17: =SUM(C17:G17)/3 -> 245509.39 | K17: =I17*2.215 -> 543803.3
A19: EBITDA Multiple | C19: 1 | E19: 2 | G19: 3 | I19: 2
A21: Estimated value of company using EBITDA model | I21: =I17*I19 -> 491018.78

Sheet Price of share
A1: =Cover!D11 -> View HR Limited
A2: Price of share - Breakdown
E4: £
A5: Estimated value of company | E5: =Ebitda!I21 -> 491018.78
A8: Shares in business | E8: 310
A10: Value per share | E10: =E5/E8 -> 1583.9315
A13: Share breakdown and value of shareholding
B14: Number of shares | C14: Class of share | D14: Value per share (£) | E14: Total value of shareholding (£)
A16: Gemma Murphy | B16: 91 | C16: Ordinary | D16: =$E$10 -> 1583.9315 | E16: =B16*D16 -> 144137.77 | H16: =200000 -> 200000 | I16: =H16/(B16+B17)*B16 -> 101111.11 | K16: =I16/D16 -> 63.835531 | L16: =B16-K16 -> 27.164469 | N16: =K16/B16 -> 0.70148935
A17: Sarah King | B17: 89 | C17: Ordinary | D17: =$E$10 -> 1583.9315 | E17: =(B17*D17)-1 -> 140968.91 | I17: =H16/(B16+B17)*B17 -> 98888.889 | K17: =I17/D17 -> 62.432552 | L17: =B17-K17 -> 26.567448 | N17: =K17/B17 -> 0.70148935
A18: Heidi Smith | B18: 20 | C18: Ordinary | D18: =$E$10 -> 1583.9315 | E18: =B18*D18 -> 31678.631
A19: Gemma Murphy | B19: 50 | C19: Ordinary B | D19: =$E$10 -> 1583.9315 | E19: =B19*D19 -> 79196.577
A20: Sarah King | B20: 50 | C20: Ordinary B | D20: =$E$10 -> 1583.9315 | E20: =B20*D20 -> 79196.577 | I20: =SUM(I16:I17) -> 200000
A21: Heidi Smith | B21: 10 | C21: Ordinary C | D21: =$E$10 -> 1583.9315 | E21: =B21*D21 -> 15839.315
B22: =SUM(B16:B21) -> 310 | E22: =SUM(E16:E21) -> 491017.78
B24: =(B21+B18)/B22 -> 0.096774194 | H24: Heidi | I24: =E18+E21 -> 47517.946

Sheet Profit & loss per accs
A1: View HR Limited
A2: EBITDA Financials
A3: Detailed Profit & Loss per accs
C5: 2025 | E5: 2024 | G5: 2023
C6: £ | E6: £ | G6: £
A8: Turnover
A9: Sales | C9: 859085 | E9: 664804 | G9: 549888
A10: Other trading income | C10: 462 | E10: 900 | G10: 420
A12: Cost of Sales
A13: Consultancy fees | C13: 43040 | E13: 50418 | G13: 43732
A14: Other direct costs | C14: 3703 | E14: 7542 | G14: 4837
C15: =-SUM(C13:C14) -> -46743 | E15: =-SUM(E13:E14) -> -57960 | G15: =-SUM(G13:G14) -> -48569
A17: GROSS PROFIT | C17: =C9+C15+C10 -> 812804 | E17: =E9+E15+E10 -> 607744 | G17: =G9+G15+G10 -> 501739
A19: Administrative Expenses
A20: Directors Salaries | C20: 61020 | E20: 61020 | G20: 60059
A21: Directors NI | C21: 4731 | E21: 4653 | G21: 4667
A22: Directors pension - defined contribution scheme | C22: 30489 | E22: 25989 | G22: 889
A23: Wages and salaries | C23: 215947 | E23: 142885 | G23: 110407
A24: Employers NI | C24: 17865 | E24: 9194 | G24: 5297
A25: Employers pensions - defined contribution scheme | C25: 4697 | E25: 3164 | G25: 2178
A26: Staff training and welfare | C26: 7970 | E26: 8781 | G26: 2283
A27: Staff entertaining | C27: 6407 | E27: 8608 | G27: 8358
A28: Staff expenses | C28: 741 | E28: 2399 | G28: 7460
A29: Travel expenses | C29: 4598 | E29: 3494 | G29: =260+2799 -> 3059
A30: Use of private residence | C30: 1142 | E30: 700 | G30: 840
A31: Hire and leasing of motor vehicles | C31: 14592 | E31: 14592 | G31: 22662
A32: Vehicle running costs | C32: 3357 | E32: 7369 | G32: 8180
A33: Computer software costs | C33: 16401 | E33: 8956 | G33: 5943
A34: Insurance | C34: 11332 | E34: 6899 | G34: 5131
A35: Printing, postage and stationery | C35: 961 | E35: 499 | G35: 106
A36: Advertising and marketing costs | C36: 30445 | E36: 19751 | G36: 13930
A37: Telecommunications | C37: 7024 | E37: 5202 | G37: 3788
A38: Accountancy fees | C38: 4381 | E38: 3191 | G38: 6591
A39: Professional fees | C39: 1129 | E39: 2152 | G39: 2410
A40: Professional subscriptions | C40: 43426 | E40: 32827 | G40: 31575
A41: Bank charges | C41: 98 | E41: 86 | G41: 29
... A46: Sundry expenses | C46: 75 | E46: -3 | G46: -1
C47: =-SUM(C20:C46) -> -500004 | E47: =-SUM(E20:E46) -> -377416 | G47: =-SUM(G20:G46) -> -307490
A49: OPERATING PROFIT | C49: =C17+C47 -> 312800 | E49: =E17+E47 -> 230328 | G49: =G17+G47 -> 194249
A51: Other interest receivable and similar income
...

Sheet Balance sheet
A1: View HR Limited
A2: EBITDA Financials
A3: Balance sheet
C5: 2025 | F5: 2024 | I5: 2023
C6: £ | D6: £ | F6: £ | G6: £ | I6: £ | J6: £
A8: Fixed Assets
A9: Intangible Assets | G9: 0 | J9: 0
A10: Tangible Assets | D10: 7899 | G10: 5721 | J10: 3459
D12: =SUM(D9:D10) -> 7899 | G12: =SUM(G9:G10) -> 5721 | J12: =SUM(J9:J10) -> 3459
A13: Current Assets
A14: Stocks | C14: 5325 | F14: 5325 | I14: 0
A15: Debtors | C15: 41871 | F15: 29367 | I15: 32225
A16: Cash at bank and in hand | C16: 325947 | F16: 337915 | I16: 286773
C18: =SUM(C14:C16) -> 373143 | F18: =SUM(F14:F16) -> 372607 | I18: =SUM(I14:I16) -> 318998
A20: Creditors: Amounts Falling Due within
A21: One Year | C21: -146811 | F21: -145254 | I21: -142249
A24: Net Current Assets (Liabilities) | D24: =C18+C21 -> 226332 | G24: =F18+F21 -> 227353 | J24: =I18+I21 -> 176749
A26: Total Assets Less Current
A27: Liabilities | D27: =D12+D24 -> 234231 | G27: =G12+G24 -> 233074 | J27: =J12+J24 -> 180208
A29: Creditors: Amounts Falling Due after
A30: More than one year | D30: -23021 | G30: -28566 | J30: -33284
A32: Provisions for liabilities
A33: Deferred Taxation | D33: -1904 | G33: -1344 | J33: -248
A35: Net Assets | D35: =D27+D30+D33 -> 209306 | G35: =G27+G30+G33 -> 203164 | J35: =J27+J30+J33 -> 146676
A37: Capital and Reserves
A38: Called up share capital | D38: 310 | G38: 310 | J38: 310
A39: Profit and Loss Account | D39: 208996 | G39: 202854 | J39: 146366
A41: Shareholders' Funds | D41: =SUM(D38:D39) -> 209306 | G41: =SUM(G38:G39) -> 203164 | J41: =SUM(J38:J39) -> 146676

Sheet Ebitda workings
A1: View HR Limited
A2: Ebitda Financials
A3: Ebitda workings | I3: adjustments | O3: Adjusted profit and loss
C5: 2025 | E5: 2024 | G5: 2023 | I5: 2025 | K5: 2024 | M5: 2023 | O5: 2025 | Q5: 2024 | S5: 2023
C6: £ | E6: £ | G6: £ | I6: £ | K6: £ | M6: £ | O6: £ | Q6: £ | S6: £
A8: Turnover
A9: Sales | C9: 859085 | E9: 664804 | G9: 549888 | O9: =C9+I9 -> 859085 | Q9: =E9+K9 -> 664804 | S9: =G9+M9 -> 549888
A10: Other trading income | C10: 462 | E10: 900 | G10: 420 | O10: =C10+I10 -> 462 | Q10: =E10+K10 -> 900 | S10: =G10+M10 -> 420
C11: =SUM(C9:C10) -> 859547 | E11: =SUM(E9:E10) -> 665704 | G11: =SUM(G9:G10) -> 550308 | I11: =SUM(I9:I10) -> 0 | K11: =SUM(K9:K10) -> 0 | M11: =SUM(M9:M10) -> 0 | O11: =C11+I11 -> 859547 | Q11: =E11+K11 -> 665704 | S11: =G11+M11 -> 550308
A12: Cost of Sales
A13: Consultancy fees | C13: 43040 | E13: 50418 | G13: 43732 | O13: =C13+I13 -> 43040 | Q13: =E13+K13 -> 50418 | S13: =G13+M13 -> 43732
A14: Other direct costs | C14: 3703 | E14: 7542 | G14: 4837 | O14: =C14+I14 -> 3703 | Q14: =E14+K14 -> 7542 | S14: =G14+M14 -> 4837
C15: =-SUM(C13:C14) -> -46743 | E15: =-SUM(E13:E14) -> -57960 | G15: =-SUM(G13:G14) -> -48569 | I15: =-SUM(I14) -> 0 | K15: =-SUM(K14) -> 0 | M15: =-SUM(M14) -> 0 | O15: =-SUM(O13:O14) -> -46743 | Q15: =-SUM(Q13:Q14) -> -57960 | S15: =-SUM(S13:S14) -> -48569
A17: GROSS PROFIT | C17: =C9+C15+C10 -> 812804 | E17: =E9+E15+E10 -> 607744 | G17: =G9+G15+G10 -> 501739 | I17: =I9+I15 -> 0 | K17: =K9+K15 -> 0 | M17: =M9+M15 -> 0 | O17: =O9+O15 -> 812342 | Q17: =Q9+Q15 -> 606844 | S17: =S9+S15 -> 501319
A19: Administrative Expenses
A20: Directors Salaries | C20: 61020 | E20: 61020 | G20: 60059 | I20: -35880 | K20: -35880 | M20: -35880 | O20: =C20+I20 -> 25140 | Q20: =E20+K20 -> 25140 | S20: =G20+M20 -> 24179
A21: Directors NI | C21: 4731 | E21: 4653 | G21: 4667 | I21: -3774 | K21: -3696 | M21: -3864 | O21: =C21+I21 -> 957 | Q21: =E21+K21 -> 957 | S21: =G21+M21 -> 803
A22: Directors pension - defined contribution scheme | C22: 30489 | E22: 25989 | G22: 889 | I22: =-889-9000 -> -9889 | K22: =-889.2+-7700 -> -8589.2 | M22: -889.2 | O22: =C22+I22 -> 20600 | Q22: =E22+K22 -> 17399.8 | S22: =G22+M22 -> -0.2
A23: Wages and salaries | C23: 215947 | E23: 142885 | G23: 110407 | I23: 60000 | O23: =C23+I23 -> 275947 | Q23: =E23+K23 -> 142885 | S23: =G23+M23 -> 110407
A24: Employers NI | C24: 17865 | E24: 9194 | G24: 5297 | I24: 8250 | O24: =C24+I24 -> 26115 | Q24: =E24+K24 -> 9194 | S24: =G24+M24 -> 5297
A25: Employers pensions - defined contribution scheme | C25: 4697 | E25: 3164 | G25: 2178 | I25: 1320.9 | O25: =C25+I25 -> 6017.9 | Q25: =E25+K25 -> 3164 | S25: =G25+M25 -> 2178
A26: Staff training and welfare | C26: 7970 | E26: 8781 | G26: 2283 | O26: =C26+I26 -> 7970 | Q26: =E26+K26 -> 8781 | S26: =G26+M26 -> 2283
A27: Staff entertaining | C27: 6407 | E27: 8608 | G27: 8358 | O27: =C27+I27 -> 6407 | Q27: =E27+K27 -> 8608 | S27: =G27+M27 -> 8358
A28: Staff expenses | C28: 741 | E28: 2399 | G28: 7460 | O28: =C28+I28 -> 741 | Q28: =E28+K28 -> 2399 | S28: =G28+M28 -> 7460
A29: Travel expenses | C29: 4598 | E29: 3494 | G29: =260+2799 -> 3059 | O29: =C29+I29 -> 4598 | Q29: =E29+K29 -> 3494 | S29: =G29+M29 -> 3059
A30: Use of private residence | C30: 1142 | E30: 700 | G30: 840 | I30: =-C30/3 -> -380.66667 | O30: =C30+I30 -> 761.33333 | Q30: =E30+K30 -> 700 | S30: =G30+M30 -> 840
A31: Hire and leasing of motor vehicles | C31: 14592 | E31: 14592 | G31: 22662 | O31: =C31+I31 -> 14592 | Q31: =E31+K31 -> 14592 | S31: =G31+M31 -> 22662
A32: Vehicle running costs | C32: 3357 | E32: 7369 | G32: 8180 | O32: =C32+I32 -> 3357 | Q32: =E32+K32 -> 7369 | S32: =G32+M32 -> 8180
A33: Computer software costs | C33: 16401 | E33: 8956 | G33: 5943 | O33: =C33+I33 -> 16401 | Q33: =E33+K33 -> 8956 | S33: =G33+M33 -> 5943
A34: Insurance | C34: 11332 | E34: 6899 | G34: 5131 | O34: =C34+I34 -> 11332 | Q34: =E34+K34 -> 6899 | S34: =G34+M34 -> 5131
A35: Printing, postage and stationery | C35: 961 | E35: 499 | G35: 106 | O35: =C35+I35 -> 961 | Q35: =E35+K35 -> 499 | S35: =G35+M35 -> 106
A36: Advertising and marketing costs | C36: 30445 | E36: 19751 | G36: 13930 | I36: 10000 | O36: =C36+I36 -> 40445 | Q36: =E36+K36 -> 19751 | S36: =G36+M36 -> 13930
A37: Telecommunications | C37: 7024 | E37: 5202 | G37: 3788 | O37: =C37+I37 -> 7024 | Q37: =E37+K37 -> 5202 | S37: =G37+M37 -> 3788
A38: Accountancy fees | C38: 4381 | E38: 3191 | G38: 6591 | O38: =C38+I38 -> 4381 | Q38: =E38+K38 -> 3191 | S38: =G38+M38 -> 6591
A39: Professional fees | C39: 1129 | E39: 2152 | G39: 2410 | O39: =C39+I39 -> 1129 | Q39: =E39+K39 -> 2152 | S39: =G39+M39 -> 2410
A40: Professional subscriptions | C40: 43426 | E40: 32827 | G40: 31575 | I40: 40000 | O40: =C40+I40 -> 83426 | Q40: =E40+K40 -> 32827 | S40: =G40+M40 -> 31575
A41: Bank charges | C41: 98 | E41: 86 | G41: 29 | O41: =C41+I41 -> 98 | Q41: =E41+K41 -> 86 | S41: =G41+M41 -> 29
A42: Charitable donations | C42: 1695 | E42: 870 | G42: 317 | O42: =C42+I42 -> 1695 | Q42: =E42+K42 -> 870 | S42: =G42+M42 -> 317
A43: Bad debts written off | C43: 5035 | E43: 1487 | G43: 0 | O43: =C43+I43 -> 5035 | Q43: =E43+K43 -> 1487 | S43: =G43+M43 -> 0
A44: Other office costs | C44: 436 | E44: 360 | G44: 0 | I44: 20000 | O44: =C44+I44 -> 20436 | Q44: =E44+K44 -> 360 | S44: =G44+M44 -> 0
...

Sheet Heidi consideration
A1: =Cover!D11 -> View HR Limited | N1: View HR Limited
A2: Ebitda Financials | N2: Ebitda Financials
C4: 2025 | E4: 2024 | G4: 2023 | I4: Avg Total | P4: 2025 | R4: 2024 | T4: 2023 | V4: Avg Total
C5: £ | E5: £ | G5: £ | P5: £ | R5: £ | T5: £
A7: Turnover | C7: ='Ebitda workings'!O9 -> 859085 | E7: ='Ebitda workings'!Q9 -> 664804 | G7: ='Ebitda workings'!S9 -> 549888 | N7: Turnover | P7: 859085 | R7: 664804 | T7: 549888
A9: Cost of Sales | C9: ='Ebitda workings'!O15 -> -46743 | E9: ='Ebitda workings'!Q15 -> -57960 | G9: ='Ebitda workings'!S15 -> -48569 | N9: Cost of Sales | P9: -46743 | R9: -57960 | T9: -48569
A11: GROSS PROFIT | C11: =SUM(C7:C10) -> 812342 | E11: =SUM(E7:E10) -> 606844 | G11: =SUM(G7:G10) -> 501319 | N11: GROSS PROFIT | P11: =SUM(P7:P10) -> 812342 | R11: =SUM(R7:R10) -> 606844 | T11: =SUM(T7:T10) -> 501319
A13: Administrative Expenses | C13: ='Ebitda workings'!O47 -> -589651.23 | E13: ='Ebitda workings'!Q47 -> -329250.8 | G13: ='Ebitda workings'!S47 -> -266856.8 | N13: Administrative Expenses | P13: -450461 | R13: -329250.8 | T13: -266856.8
A15: Other operating income | C15: ='Ebitda workings'!O10 -> 462 | E15: ='Ebitda workings'!Q10 -> 900 | G15: ='Ebitda workings'!S10 -> 420 | N15: Other operating income | P15: 462 | R15: 900 | T15: 420
A17: EBITDA | C17: =SUM(C11:C16) -> 223152.77 | E17: =SUM(E11:E16) -> 278493.2 | G17: =SUM(G11:G16) -> 234882.2 | I17: =SUM(C17:G17)/3 -> 245509.39 | K17: =I17*2.215 -> 543803.3 | N17: EBITDA | P17: =SUM(P11:P16) -> 362343 | R17: =SUM(R11:R16) -> 278493.2 | T17: =SUM(T11:T16) -> 234882.2
A19: EBITDA Multiple | C19: 1 | E19: 2 | G19: 3 | I19: 1.8 | K19: 3 | N19: Weighted EBITDA | P19: 0.5 | R19: 0.3 | T19: 0.2
A21: Estimated value of company using EBITDA model | I21: =I17*I19 -> 441916.9 | P21: =P17*P19 -> 181171.5 | R21: =R17*R19 -> 83547.96 | T21: =T17*T19 -> 46976.44 | V21: =P21+R21+T21 -> 311695.9
N23: EBITDA multiple | P23: 1 | R23: 2 | T23: 3 | V23: 2.2
A24: Factors to reduce EBITDA
C25: Jaluch payment remaining | N25: Estimated value of company using EBITDA model | V25: =V21*V23 -> 685730.98
C27: Office refurbishment | N27: Factors to reduce EBITDA
P28: Jaluch payment remaining
C29: Website
P30: Office refurbishment
C31: Possible replacement senior consultant
P32: Website
A33: Adjusted EBITDA | I33: =I21-I25-I27-I29-I31 -> 441916.9
P34: Possible replacement senior consultant
N36: Adjusted EBITDA | V36: =V25-SUM(V28:V34) -> 685730.98
E40: £
A41: Estimated value of company | E41: =I33 -> 441916.9
A44: Shares in business | E44: ='Price of share'!E8 -> 310
A46: Value per share | E46: =E41/E44 -> 1425.5384
A49: Share breakdown and value of shareholding
B50: Number of shares | C50: Class of share | D50: Value per share (£) | E50: Total value of shareholding (£)
A52: Gemma Murphy | B52: 91 | C52: Ordinary | D52: =$E$46 -> 1425.5384 | E52: =B52*D52 -> 129723.99
A53: Sarah King | B53: 89 | C53: Ordinary | D53: =$E$46 -> 1425.5384 | E53: =B53*D53 -> 126872.92
A54: Heidi Smith | B54: 20 | C54: Ordinary | D54: =$E$46 -> 1425.5384 | E54: =B54*D54 -> 28510.768
A55: Gemma Murphy | B55: 50 | C55: Ordinary B | D55: =$E$46 -> 1425.5384 | E55: =B55*D55 -> 71276.919
A56: Sarah King | B56: 50 | C56: Ordianry B | D56: =$E$46 -> 1425.5384 | E56: =B56*D56 -> 71276.919
A57: Heidi Smith | B57: 10 | C57: Ordinary C | D57: =$E$46 -> 1425.5384 | E57: =B57*D57 -> 14255.384
B58: =SUM(B52:B57) -> 310 | E58: =SUM(E52:E57) -> 441916.9
A60: Heidi Share | E60: =E57+E54 -> 42766.152

Sheet payroll
